    void foo() throws InterruptedException
    {

            try
            {

            }
            catch (Exception e)
            {
                return;
            }

        }

